2023-05-04 14:46:46,162 ERROR [capa] [CapaProcessWorker.py:59] - 'MPEqpModule' object has no attribute 'moduleType'
2023-05-04 14:46:46,186 ERROR [capa] [CapaProcessWorker.py:60] - ['  File "C:\\Users\\wisol\\AppData\\Local\\JetBrains\\Toolbox\\apps\\PyCharm-P\\ch-0\\231.8109.197\\plugins\\python\\helpers\\pydev\\pydevd.py", line 2195, in <module>\n    main()\n', '  File "C:\\Users\\wisol\\AppData\\Local\\JetBrains\\Toolbox\\apps\\PyCharm-P\\ch-0\\231.8109.197\\plugins\\python\\helpers\\pydev\\pydevd.py", line 2177, in main\n    globals = debugger.run(setup[\'file\'], None, None, is_module)\n', '  File "C:\\Users\\wisol\\AppData\\Local\\JetBrains\\Toolbox\\apps\\PyCharm-P\\ch-0\\231.8109.197\\plugins\\python\\helpers\\pydev\\pydevd.py", line 1489, in run\n    return self._exec(is_module, entry_point_fn, module_name, file, globals, locals)\n', '  File "C:\\Users\\wisol\\AppData\\Local\\JetBrains\\Toolbox\\apps\\PyCharm-P\\ch-0\\231.8109.197\\plugins\\python\\helpers\\pydev\\pydevd.py", line 1496, in _exec\n    pydev_imports.execfile(file, globals, locals)  # execute the script\n', '  File "C:\\Users\\wisol\\AppData\\Local\\JetBrains\\Toolbox\\apps\\PyCharm-P\\ch-0\\231.8109.197\\plugins\\python\\helpers\\pydev\\_pydev_imps\\_pydev_execfile.py", line 18, in execfile\n    exec(compile(contents+"\\n", file, \'exec\'), glob, loc)\n', '  File "C:\\webpro\\pythonProject\\fdcmp\\manage.py", line 22, in <module>\n    main()\n', '  File "C:\\webpro\\pythonProject\\fdcmp\\manage.py", line 18, in main\n    execute_from_command_line(sys.argv)\n', '  File "C:\\webpro\\pythonProject\\fdcmp\\venv\\lib\\site-packages\\django\\core\\management\\__init__.py", line 446, in execute_from_command_line\n    utility.execute()\n', '  File "C:\\webpro\\pythonProject\\fdcmp\\venv\\lib\\site-packages\\django\\core\\management\\__init__.py", line 398, in execute\n    autoreload.check_errors(django.setup)()\n', '  File "C:\\webpro\\pythonProject\\fdcmp\\venv\\lib\\site-packages\\django\\utils\\autoreload.py", line 64, in wrapper\n    fn(*args, **kwargs)\n', '  File "C:\\webpro\\pythonProject\\fdcmp\\venv\\lib\\site-packages\\django\\__init__.py", line 24, in setup\n    apps.populate(settings.INSTALLED_APPS)\n', '  File "C:\\webpro\\pythonProject\\fdcmp\\venv\\lib\\site-packages\\django\\apps\\registry.py", line 124, in populate\n    app_config.ready()\n', '  File "C:\\webpro\\pythonProject\\fdcmp\\capa\\apps.py", line 14, in ready\n    capaProcessWorker()\n', '  File "C:\\webpro\\pythonProject\\fdcmp\\capa\\Process\\CapaProcessWorker.py", line 60, in capaProcessWorker\n    logger.error(traceback.format_stack())\n']
2023-05-04 14:46:56,436 ERROR [capa] [CapaProcessWorker.py:59] - 'MPEqpModule' object has no attribute 'moduleType'
2023-05-04 14:46:56,439 ERROR [capa] [CapaProcessWorker.py:60] - ['  File "C:\\Users\\wisol\\AppData\\Local\\JetBrains\\Toolbox\\apps\\PyCharm-P\\ch-0\\231.8109.197\\plugins\\python\\helpers\\pydev\\pydevd.py", line 2195, in <module>\n    main()\n', '  File "C:\\Users\\wisol\\AppData\\Local\\JetBrains\\Toolbox\\apps\\PyCharm-P\\ch-0\\231.8109.197\\plugins\\python\\helpers\\pydev\\pydevd.py", line 2177, in main\n    globals = debugger.run(setup[\'file\'], None, None, is_module)\n', '  File "C:\\Users\\wisol\\AppData\\Local\\JetBrains\\Toolbox\\apps\\PyCharm-P\\ch-0\\231.8109.197\\plugins\\python\\helpers\\pydev\\pydevd.py", line 1489, in run\n    return self._exec(is_module, entry_point_fn, module_name, file, globals, locals)\n', '  File "C:\\Users\\wisol\\AppData\\Local\\JetBrains\\Toolbox\\apps\\PyCharm-P\\ch-0\\231.8109.197\\plugins\\python\\helpers\\pydev\\pydevd.py", line 1496, in _exec\n    pydev_imports.execfile(file, globals, locals)  # execute the script\n', '  File "C:\\Users\\wisol\\AppData\\Local\\JetBrains\\Toolbox\\apps\\PyCharm-P\\ch-0\\231.8109.197\\plugins\\python\\helpers\\pydev\\_pydev_imps\\_pydev_execfile.py", line 18, in execfile\n    exec(compile(contents+"\\n", file, \'exec\'), glob, loc)\n', '  File "C:\\webpro\\pythonProject\\fdcmp\\manage.py", line 22, in <module>\n    main()\n', '  File "C:\\webpro\\pythonProject\\fdcmp\\manage.py", line 18, in main\n    execute_from_command_line(sys.argv)\n', '  File "C:\\webpro\\pythonProject\\fdcmp\\venv\\lib\\site-packages\\django\\core\\management\\__init__.py", line 446, in execute_from_command_line\n    utility.execute()\n', '  File "C:\\webpro\\pythonProject\\fdcmp\\venv\\lib\\site-packages\\django\\core\\management\\__init__.py", line 398, in execute\n    autoreload.check_errors(django.setup)()\n', '  File "C:\\webpro\\pythonProject\\fdcmp\\venv\\lib\\site-packages\\django\\utils\\autoreload.py", line 64, in wrapper\n    fn(*args, **kwargs)\n', '  File "C:\\webpro\\pythonProject\\fdcmp\\venv\\lib\\site-packages\\django\\__init__.py", line 24, in setup\n    apps.populate(settings.INSTALLED_APPS)\n', '  File "C:\\webpro\\pythonProject\\fdcmp\\venv\\lib\\site-packages\\django\\apps\\registry.py", line 124, in populate\n    app_config.ready()\n', '  File "C:\\webpro\\pythonProject\\fdcmp\\capa\\apps.py", line 14, in ready\n    capaProcessWorker()\n', '  File "C:\\webpro\\pythonProject\\fdcmp\\capa\\Process\\CapaProcessWorker.py", line 60, in capaProcessWorker\n    logger.error(traceback.format_stack())\n']
2023-05-04 14:47:06,720 ERROR [capa] [CapaProcessWorker.py:59] - 'MPEqpModule' object has no attribute 'moduleType'
2023-05-04 14:47:06,723 ERROR [capa] [CapaProcessWorker.py:60] - ['  File "C:\\Users\\wisol\\AppData\\Local\\JetBrains\\Toolbox\\apps\\PyCharm-P\\ch-0\\231.8109.197\\plugins\\python\\helpers\\pydev\\pydevd.py", line 2195, in <module>\n    main()\n', '  File "C:\\Users\\wisol\\AppData\\Local\\JetBrains\\Toolbox\\apps\\PyCharm-P\\ch-0\\231.8109.197\\plugins\\python\\helpers\\pydev\\pydevd.py", line 2177, in main\n    globals = debugger.run(setup[\'file\'], None, None, is_module)\n', '  File "C:\\Users\\wisol\\AppData\\Local\\JetBrains\\Toolbox\\apps\\PyCharm-P\\ch-0\\231.8109.197\\plugins\\python\\helpers\\pydev\\pydevd.py", line 1489, in run\n    return self._exec(is_module, entry_point_fn, module_name, file, globals, locals)\n', '  File "C:\\Users\\wisol\\AppData\\Local\\JetBrains\\Toolbox\\apps\\PyCharm-P\\ch-0\\231.8109.197\\plugins\\python\\helpers\\pydev\\pydevd.py", line 1496, in _exec\n    pydev_imports.execfile(file, globals, locals)  # execute the script\n', '  File "C:\\Users\\wisol\\AppData\\Local\\JetBrains\\Toolbox\\apps\\PyCharm-P\\ch-0\\231.8109.197\\plugins\\python\\helpers\\pydev\\_pydev_imps\\_pydev_execfile.py", line 18, in execfile\n    exec(compile(contents+"\\n", file, \'exec\'), glob, loc)\n', '  File "C:\\webpro\\pythonProject\\fdcmp\\manage.py", line 22, in <module>\n    main()\n', '  File "C:\\webpro\\pythonProject\\fdcmp\\manage.py", line 18, in main\n    execute_from_command_line(sys.argv)\n', '  File "C:\\webpro\\pythonProject\\fdcmp\\venv\\lib\\site-packages\\django\\core\\management\\__init__.py", line 446, in execute_from_command_line\n    utility.execute()\n', '  File "C:\\webpro\\pythonProject\\fdcmp\\venv\\lib\\site-packages\\django\\core\\management\\__init__.py", line 398, in execute\n    autoreload.check_errors(django.setup)()\n', '  File "C:\\webpro\\pythonProject\\fdcmp\\venv\\lib\\site-packages\\django\\utils\\autoreload.py", line 64, in wrapper\n    fn(*args, **kwargs)\n', '  File "C:\\webpro\\pythonProject\\fdcmp\\venv\\lib\\site-packages\\django\\__init__.py", line 24, in setup\n    apps.populate(settings.INSTALLED_APPS)\n', '  File "C:\\webpro\\pythonProject\\fdcmp\\venv\\lib\\site-packages\\django\\apps\\registry.py", line 124, in populate\n    app_config.ready()\n', '  File "C:\\webpro\\pythonProject\\fdcmp\\capa\\apps.py", line 14, in ready\n    capaProcessWorker()\n', '  File "C:\\webpro\\pythonProject\\fdcmp\\capa\\Process\\CapaProcessWorker.py", line 60, in capaProcessWorker\n    logger.error(traceback.format_stack())\n']
2023-05-04 14:47:16,986 ERROR [capa] [CapaProcessWorker.py:59] - 'MPEqpModule' object has no attribute 'moduleType'
2023-05-04 14:47:17,012 ERROR [capa] [CapaProcessWorker.py:60] - ['  File "C:\\Users\\wisol\\AppData\\Local\\JetBrains\\Toolbox\\apps\\PyCharm-P\\ch-0\\231.8109.197\\plugins\\python\\helpers\\pydev\\pydevd.py", line 2195, in <module>\n    main()\n', '  File "C:\\Users\\wisol\\AppData\\Local\\JetBrains\\Toolbox\\apps\\PyCharm-P\\ch-0\\231.8109.197\\plugins\\python\\helpers\\pydev\\pydevd.py", line 2177, in main\n    globals = debugger.run(setup[\'file\'], None, None, is_module)\n', '  File "C:\\Users\\wisol\\AppData\\Local\\JetBrains\\Toolbox\\apps\\PyCharm-P\\ch-0\\231.8109.197\\plugins\\python\\helpers\\pydev\\pydevd.py", line 1489, in run\n    return self._exec(is_module, entry_point_fn, module_name, file, globals, locals)\n', '  File "C:\\Users\\wisol\\AppData\\Local\\JetBrains\\Toolbox\\apps\\PyCharm-P\\ch-0\\231.8109.197\\plugins\\python\\helpers\\pydev\\pydevd.py", line 1496, in _exec\n    pydev_imports.execfile(file, globals, locals)  # execute the script\n', '  File "C:\\Users\\wisol\\AppData\\Local\\JetBrains\\Toolbox\\apps\\PyCharm-P\\ch-0\\231.8109.197\\plugins\\python\\helpers\\pydev\\_pydev_imps\\_pydev_execfile.py", line 18, in execfile\n    exec(compile(contents+"\\n", file, \'exec\'), glob, loc)\n', '  File "C:\\webpro\\pythonProject\\fdcmp\\manage.py", line 22, in <module>\n    main()\n', '  File "C:\\webpro\\pythonProject\\fdcmp\\manage.py", line 18, in main\n    execute_from_command_line(sys.argv)\n', '  File "C:\\webpro\\pythonProject\\fdcmp\\venv\\lib\\site-packages\\django\\core\\management\\__init__.py", line 446, in execute_from_command_line\n    utility.execute()\n', '  File "C:\\webpro\\pythonProject\\fdcmp\\venv\\lib\\site-packages\\django\\core\\management\\__init__.py", line 398, in execute\n    autoreload.check_errors(django.setup)()\n', '  File "C:\\webpro\\pythonProject\\fdcmp\\venv\\lib\\site-packages\\django\\utils\\autoreload.py", line 64, in wrapper\n    fn(*args, **kwargs)\n', '  File "C:\\webpro\\pythonProject\\fdcmp\\venv\\lib\\site-packages\\django\\__init__.py", line 24, in setup\n    apps.populate(settings.INSTALLED_APPS)\n', '  File "C:\\webpro\\pythonProject\\fdcmp\\venv\\lib\\site-packages\\django\\apps\\registry.py", line 124, in populate\n    app_config.ready()\n', '  File "C:\\webpro\\pythonProject\\fdcmp\\capa\\apps.py", line 14, in ready\n    capaProcessWorker()\n', '  File "C:\\webpro\\pythonProject\\fdcmp\\capa\\Process\\CapaProcessWorker.py", line 60, in capaProcessWorker\n    logger.error(traceback.format_stack())\n']
2023-05-04 16:01:15,076 ERROR [capa] [CapaProcessWorker.py:69] - daemonic processes are not allowed to have children
2023-05-04 16:01:15,091 ERROR [capa] [CapaProcessWorker.py:70] - ['  File "<string>", line 1, in <module>\n', '  File "C:\\Users\\wisol\\AppData\\Local\\Programs\\Python\\Python310\\lib\\multiprocessing\\spawn.py", line 116, in spawn_main\n    exitcode = _main(fd, parent_sentinel)\n', '  File "C:\\Users\\wisol\\AppData\\Local\\Programs\\Python\\Python310\\lib\\multiprocessing\\spawn.py", line 129, in _main\n    return self._bootstrap(parent_sentinel)\n', '  File "C:\\Users\\wisol\\AppData\\Local\\Programs\\Python\\Python310\\lib\\multiprocessing\\process.py", line 314, in _bootstrap\n    self.run()\n', '  File "C:\\Users\\wisol\\AppData\\Local\\Programs\\Python\\Python310\\lib\\multiprocessing\\process.py", line 108, in run\n    self._target(*self._args, **self._kwargs)\n', '  File "C:\\webpro\\pythonProject\\fdcmp\\capa\\Process\\CapaProcessWorker.py", line 29, in capaPWorker\n    apps.populate([\'capa\'])\n', '  File "C:\\webpro\\pythonProject\\fdcmp\\venv\\lib\\site-packages\\django\\apps\\registry.py", line 124, in populate\n    app_config.ready()\n', '  File "C:\\webpro\\pythonProject\\fdcmp\\capa\\apps.py", line 14, in ready\n    capaProcessWorker()\n', '  File "C:\\webpro\\pythonProject\\fdcmp\\capa\\Process\\CapaProcessWorker.py", line 70, in capaProcessWorker\n    logger.error(traceback.format_stack())\n']
2023-05-04 16:01:25,337 ERROR [capa] [CapaProcessWorker.py:69] - daemonic processes are not allowed to have children
2023-05-04 16:01:25,339 ERROR [capa] [CapaProcessWorker.py:70] - ['  File "<string>", line 1, in <module>\n', '  File "C:\\Users\\wisol\\AppData\\Local\\Programs\\Python\\Python310\\lib\\multiprocessing\\spawn.py", line 116, in spawn_main\n    exitcode = _main(fd, parent_sentinel)\n', '  File "C:\\Users\\wisol\\AppData\\Local\\Programs\\Python\\Python310\\lib\\multiprocessing\\spawn.py", line 129, in _main\n    return self._bootstrap(parent_sentinel)\n', '  File "C:\\Users\\wisol\\AppData\\Local\\Programs\\Python\\Python310\\lib\\multiprocessing\\process.py", line 314, in _bootstrap\n    self.run()\n', '  File "C:\\Users\\wisol\\AppData\\Local\\Programs\\Python\\Python310\\lib\\multiprocessing\\process.py", line 108, in run\n    self._target(*self._args, **self._kwargs)\n', '  File "C:\\webpro\\pythonProject\\fdcmp\\capa\\Process\\CapaProcessWorker.py", line 29, in capaPWorker\n    apps.populate([\'capa\'])\n', '  File "C:\\webpro\\pythonProject\\fdcmp\\venv\\lib\\site-packages\\django\\apps\\registry.py", line 124, in populate\n    app_config.ready()\n', '  File "C:\\webpro\\pythonProject\\fdcmp\\capa\\apps.py", line 14, in ready\n    capaProcessWorker()\n', '  File "C:\\webpro\\pythonProject\\fdcmp\\capa\\Process\\CapaProcessWorker.py", line 70, in capaProcessWorker\n    logger.error(traceback.format_stack())\n']
2023-05-04 16:13:23,962 INFO [capa] [CapaProcessWorker.py:32] - start process moduleId=41
2023-05-04 16:22:25,395 INFO [capa] [CapaProcessWorker.py:32] - start process moduleId=41
2023-05-04 16:22:46,810 INFO [capa] [CapaProcessWorker.py:32] - start process moduleId=41
2023-05-04 16:23:28,671 INFO [capa] [CapaProcessWorker.py:32] - start process moduleId=41
2023-05-04 16:24:14,998 INFO [capa] [CapaProcessWorker.py:32] - start process moduleId=41
2023-05-04 16:24:42,798 INFO [capa] [CapaProcessWorker.py:32] - start process moduleId=41
2023-05-04 16:25:36,213 INFO [capa] [CapaProcessWorker.py:32] - start process moduleId=41
2023-05-04 16:53:26,319 INFO [capa] [CapaProcessWorker.py:35] - start process moduleId=41
2023-05-04 16:54:37,637 INFO [capa] [CapaProcessWorker.py:35] - start process moduleId=41
2023-05-04 16:55:37,889 INFO [capa] [CapaProcessWorker.py:35] - start process moduleId=41
2023-05-04 16:55:38,001 ERROR [capa] [CapaProcessWorker.py:44] - bFdcAPI.Capa.Dto.TrainSchedulerHistory.TrainSchedulerHistoryResDto() argument after ** must be a mapping, not str
2023-05-04 16:55:38,006 ERROR [capa] [CapaProcessWorker.py:45] - ['  File "<string>", line 1, in <module>\n', '  File "C:\\Users\\wisol\\AppData\\Local\\Programs\\Python\\Python310\\lib\\multiprocessing\\spawn.py", line 116, in spawn_main\n    exitcode = _main(fd, parent_sentinel)\n', '  File "C:\\Users\\wisol\\AppData\\Local\\Programs\\Python\\Python310\\lib\\multiprocessing\\spawn.py", line 129, in _main\n    return self._bootstrap(parent_sentinel)\n', '  File "C:\\Users\\wisol\\AppData\\Local\\Programs\\Python\\Python310\\lib\\multiprocessing\\process.py", line 314, in _bootstrap\n    self.run()\n', '  File "C:\\Users\\wisol\\AppData\\Local\\Programs\\Python\\Python310\\lib\\multiprocessing\\process.py", line 108, in run\n    self._target(*self._args, **self._kwargs)\n', '  File "C:\\webpro\\pythonProject\\fdcmp\\capa\\Process\\CapaProcessWorker.py", line 45, in capaPWorker\n    logger.error(traceback.format_stack())\n']
2023-05-04 16:55:46,990 ERROR [capa] [CapaProcessWorker.py:44] - bFdcAPI.Capa.Dto.TrainSchedulerHistory.TrainSchedulerHistoryResDto() argument after ** must be a mapping, not str
2023-05-04 16:55:46,993 ERROR [capa] [CapaProcessWorker.py:45] - ['  File "<string>", line 1, in <module>\n', '  File "C:\\Users\\wisol\\AppData\\Local\\Programs\\Python\\Python310\\lib\\multiprocessing\\spawn.py", line 116, in spawn_main\n    exitcode = _main(fd, parent_sentinel)\n', '  File "C:\\Users\\wisol\\AppData\\Local\\Programs\\Python\\Python310\\lib\\multiprocessing\\spawn.py", line 129, in _main\n    return self._bootstrap(parent_sentinel)\n', '  File "C:\\Users\\wisol\\AppData\\Local\\Programs\\Python\\Python310\\lib\\multiprocessing\\process.py", line 314, in _bootstrap\n    self.run()\n', '  File "C:\\Users\\wisol\\AppData\\Local\\Programs\\Python\\Python310\\lib\\multiprocessing\\process.py", line 108, in run\n    self._target(*self._args, **self._kwargs)\n', '  File "C:\\webpro\\pythonProject\\fdcmp\\capa\\Process\\CapaProcessWorker.py", line 45, in capaPWorker\n    logger.error(traceback.format_stack())\n']
2023-05-04 16:56:12,598 ERROR [capa] [CapaProcessWorker.py:44] - bFdcAPI.Capa.Dto.TrainSchedulerHistory.TrainSchedulerHistoryResDto() argument after ** must be a mapping, not str
2023-05-04 16:56:12,602 ERROR [capa] [CapaProcessWorker.py:45] - ['  File "<string>", line 1, in <module>\n', '  File "C:\\Users\\wisol\\AppData\\Local\\Programs\\Python\\Python310\\lib\\multiprocessing\\spawn.py", line 116, in spawn_main\n    exitcode = _main(fd, parent_sentinel)\n', '  File "C:\\Users\\wisol\\AppData\\Local\\Programs\\Python\\Python310\\lib\\multiprocessing\\spawn.py", line 129, in _main\n    return self._bootstrap(parent_sentinel)\n', '  File "C:\\Users\\wisol\\AppData\\Local\\Programs\\Python\\Python310\\lib\\multiprocessing\\process.py", line 314, in _bootstrap\n    self.run()\n', '  File "C:\\Users\\wisol\\AppData\\Local\\Programs\\Python\\Python310\\lib\\multiprocessing\\process.py", line 108, in run\n    self._target(*self._args, **self._kwargs)\n', '  File "C:\\webpro\\pythonProject\\fdcmp\\capa\\Process\\CapaProcessWorker.py", line 45, in capaPWorker\n    logger.error(traceback.format_stack())\n']
2023-05-04 16:56:44,746 ERROR [capa] [CapaProcessWorker.py:44] - bFdcAPI.Capa.Dto.TrainSchedulerHistory.TrainSchedulerHistoryResDto() argument after ** must be a mapping, not str
2023-05-04 16:56:44,752 ERROR [capa] [CapaProcessWorker.py:45] - ['  File "<string>", line 1, in <module>\n', '  File "C:\\Users\\wisol\\AppData\\Local\\Programs\\Python\\Python310\\lib\\multiprocessing\\spawn.py", line 116, in spawn_main\n    exitcode = _main(fd, parent_sentinel)\n', '  File "C:\\Users\\wisol\\AppData\\Local\\Programs\\Python\\Python310\\lib\\multiprocessing\\spawn.py", line 129, in _main\n    return self._bootstrap(parent_sentinel)\n', '  File "C:\\Users\\wisol\\AppData\\Local\\Programs\\Python\\Python310\\lib\\multiprocessing\\process.py", line 314, in _bootstrap\n    self.run()\n', '  File "C:\\Users\\wisol\\AppData\\Local\\Programs\\Python\\Python310\\lib\\multiprocessing\\process.py", line 108, in run\n    self._target(*self._args, **self._kwargs)\n', '  File "C:\\webpro\\pythonProject\\fdcmp\\capa\\Process\\CapaProcessWorker.py", line 45, in capaPWorker\n    logger.error(traceback.format_stack())\n']
2023-05-04 16:57:13,306 INFO [capa] [CapaProcessWorker.py:35] - start process moduleId=41
2023-05-12 15:27:14,722 INFO [capa] [CapaProcessWorker.py:30] - start process moduleId=41
2023-05-12 15:34:51,716 INFO [capa] [CapaProcessWorker.py:30] - start process moduleId=41
2023-05-12 15:35:24,971 ERROR [capa] [CapaSchedulerWorker.py:38] - 'TrainValidDataUpdateReqDto' object is not iterable
2023-05-12 15:35:29,662 ERROR [capa] [CapaSchedulerWorker.py:39] - ['  File "<string>", line 1, in <module>\n', '  File "C:\\Users\\wisol\\AppData\\Local\\Programs\\Python\\Python310\\lib\\multiprocessing\\spawn.py", line 116, in spawn_main\n    exitcode = _main(fd, parent_sentinel)\n', '  File "C:\\Users\\wisol\\AppData\\Local\\Programs\\Python\\Python310\\lib\\multiprocessing\\spawn.py", line 129, in _main\n    return self._bootstrap(parent_sentinel)\n', '  File "C:\\Users\\wisol\\AppData\\Local\\Programs\\Python\\Python310\\lib\\multiprocessing\\process.py", line 314, in _bootstrap\n    self.run()\n', '  File "C:\\Users\\wisol\\AppData\\Local\\Programs\\Python\\Python310\\lib\\multiprocessing\\process.py", line 108, in run\n    self._target(*self._args, **self._kwargs)\n', '  File "C:\\webpro\\pythonProject\\fdcmp\\capa\\Process\\CapaProcessWorker.py", line 34, in capaPWorker\n    capaSchedulerWorker.start()\n', '  File "C:\\webpro\\pythonProject\\fdcmp\\capa\\Process\\CapaSchedulerWorker.py", line 39, in start\n    logging.getLogger("capa").error(traceback.format_stack())\n']
2023-05-12 15:35:30,239 ERROR [capa] [CapaSchedulerWorker.py:62] - TrainLogicUpdateReqDto.__init__() missing 1 required positional argument: 'modelType'
2023-05-12 15:35:30,241 ERROR [capa] [CapaSchedulerWorker.py:63] - ['  File "<string>", line 1, in <module>\n', '  File "C:\\Users\\wisol\\AppData\\Local\\Programs\\Python\\Python310\\lib\\multiprocessing\\spawn.py", line 116, in spawn_main\n    exitcode = _main(fd, parent_sentinel)\n', '  File "C:\\Users\\wisol\\AppData\\Local\\Programs\\Python\\Python310\\lib\\multiprocessing\\spawn.py", line 129, in _main\n    return self._bootstrap(parent_sentinel)\n', '  File "C:\\Users\\wisol\\AppData\\Local\\Programs\\Python\\Python310\\lib\\multiprocessing\\process.py", line 314, in _bootstrap\n    self.run()\n', '  File "C:\\Users\\wisol\\AppData\\Local\\Programs\\Python\\Python310\\lib\\multiprocessing\\process.py", line 108, in run\n    self._target(*self._args, **self._kwargs)\n', '  File "C:\\webpro\\pythonProject\\fdcmp\\capa\\Process\\CapaProcessWorker.py", line 34, in capaPWorker\n    capaSchedulerWorker.start()\n', '  File "C:\\webpro\\pythonProject\\fdcmp\\capa\\Process\\CapaSchedulerWorker.py", line 63, in start\n    logging.getLogger("capa").error(traceback.format_stack())\n']
2023-05-12 15:35:30,483 ERROR [capa] [CapaSchedulerWorker.py:78] - PredictParamInfoResDto.__init__() got an unexpected keyword argument 'detail'
2023-05-12 15:35:30,484 ERROR [capa] [CapaSchedulerWorker.py:79] - ['  File "<string>", line 1, in <module>\n', '  File "C:\\Users\\wisol\\AppData\\Local\\Programs\\Python\\Python310\\lib\\multiprocessing\\spawn.py", line 116, in spawn_main\n    exitcode = _main(fd, parent_sentinel)\n', '  File "C:\\Users\\wisol\\AppData\\Local\\Programs\\Python\\Python310\\lib\\multiprocessing\\spawn.py", line 129, in _main\n    return self._bootstrap(parent_sentinel)\n', '  File "C:\\Users\\wisol\\AppData\\Local\\Programs\\Python\\Python310\\lib\\multiprocessing\\process.py", line 314, in _bootstrap\n    self.run()\n', '  File "C:\\Users\\wisol\\AppData\\Local\\Programs\\Python\\Python310\\lib\\multiprocessing\\process.py", line 108, in run\n    self._target(*self._args, **self._kwargs)\n', '  File "C:\\webpro\\pythonProject\\fdcmp\\capa\\Process\\CapaProcessWorker.py", line 34, in capaPWorker\n    capaSchedulerWorker.start()\n', '  File "C:\\webpro\\pythonProject\\fdcmp\\capa\\Process\\CapaSchedulerWorker.py", line 79, in start\n    logging.getLogger("capa").error(traceback.format_stack())\n']
2023-05-12 15:42:19,899 INFO [capa] [CapaProcessWorker.py:30] - start process moduleId=41
2023-05-12 15:44:04,062 INFO [capa] [CapaProcessWorker.py:30] - start process moduleId=41
2023-05-12 15:44:54,475 ERROR [capa] [CapaSchedulerWorker.py:38] - TrainValidDataResDto.__init__() got an unexpected keyword argument 'detail'
2023-05-12 15:44:54,481 ERROR [capa] [CapaSchedulerWorker.py:39] - ['  File "<string>", line 1, in <module>\n', '  File "C:\\Users\\wisol\\AppData\\Local\\Programs\\Python\\Python310\\lib\\multiprocessing\\spawn.py", line 116, in spawn_main\n    exitcode = _main(fd, parent_sentinel)\n', '  File "C:\\Users\\wisol\\AppData\\Local\\Programs\\Python\\Python310\\lib\\multiprocessing\\spawn.py", line 129, in _main\n    return self._bootstrap(parent_sentinel)\n', '  File "C:\\Users\\wisol\\AppData\\Local\\Programs\\Python\\Python310\\lib\\multiprocessing\\process.py", line 314, in _bootstrap\n    self.run()\n', '  File "C:\\Users\\wisol\\AppData\\Local\\Programs\\Python\\Python310\\lib\\multiprocessing\\process.py", line 108, in run\n    self._target(*self._args, **self._kwargs)\n', '  File "C:\\webpro\\pythonProject\\fdcmp\\capa\\Process\\CapaProcessWorker.py", line 34, in capaPWorker\n    capaSchedulerWorker.start()\n', '  File "C:\\webpro\\pythonProject\\fdcmp\\capa\\Process\\CapaSchedulerWorker.py", line 39, in start\n    logging.getLogger("capa").error(traceback.format_stack())\n']
2023-05-12 15:44:54,891 ERROR [capa] [CapaSchedulerWorker.py:62] - TrainLogicUpdateReqDto.__init__() missing 1 required positional argument: 'modelType'
2023-05-12 15:44:54,892 ERROR [capa] [CapaSchedulerWorker.py:63] - ['  File "<string>", line 1, in <module>\n', '  File "C:\\Users\\wisol\\AppData\\Local\\Programs\\Python\\Python310\\lib\\multiprocessing\\spawn.py", line 116, in spawn_main\n    exitcode = _main(fd, parent_sentinel)\n', '  File "C:\\Users\\wisol\\AppData\\Local\\Programs\\Python\\Python310\\lib\\multiprocessing\\spawn.py", line 129, in _main\n    return self._bootstrap(parent_sentinel)\n', '  File "C:\\Users\\wisol\\AppData\\Local\\Programs\\Python\\Python310\\lib\\multiprocessing\\process.py", line 314, in _bootstrap\n    self.run()\n', '  File "C:\\Users\\wisol\\AppData\\Local\\Programs\\Python\\Python310\\lib\\multiprocessing\\process.py", line 108, in run\n    self._target(*self._args, **self._kwargs)\n', '  File "C:\\webpro\\pythonProject\\fdcmp\\capa\\Process\\CapaProcessWorker.py", line 34, in capaPWorker\n    capaSchedulerWorker.start()\n', '  File "C:\\webpro\\pythonProject\\fdcmp\\capa\\Process\\CapaSchedulerWorker.py", line 63, in start\n    logging.getLogger("capa").error(traceback.format_stack())\n']
2023-05-12 15:44:55,246 ERROR [capa] [CapaSchedulerWorker.py:78] - PredictParamInfoResDto.__init__() got an unexpected keyword argument 'detail'
2023-05-12 15:44:55,247 ERROR [capa] [CapaSchedulerWorker.py:79] - ['  File "<string>", line 1, in <module>\n', '  File "C:\\Users\\wisol\\AppData\\Local\\Programs\\Python\\Python310\\lib\\multiprocessing\\spawn.py", line 116, in spawn_main\n    exitcode = _main(fd, parent_sentinel)\n', '  File "C:\\Users\\wisol\\AppData\\Local\\Programs\\Python\\Python310\\lib\\multiprocessing\\spawn.py", line 129, in _main\n    return self._bootstrap(parent_sentinel)\n', '  File "C:\\Users\\wisol\\AppData\\Local\\Programs\\Python\\Python310\\lib\\multiprocessing\\process.py", line 314, in _bootstrap\n    self.run()\n', '  File "C:\\Users\\wisol\\AppData\\Local\\Programs\\Python\\Python310\\lib\\multiprocessing\\process.py", line 108, in run\n    self._target(*self._args, **self._kwargs)\n', '  File "C:\\webpro\\pythonProject\\fdcmp\\capa\\Process\\CapaProcessWorker.py", line 34, in capaPWorker\n    capaSchedulerWorker.start()\n', '  File "C:\\webpro\\pythonProject\\fdcmp\\capa\\Process\\CapaSchedulerWorker.py", line 79, in start\n    logging.getLogger("capa").error(traceback.format_stack())\n']
2023-05-12 15:45:11,204 INFO [capa] [CapaProcessWorker.py:30] - start process moduleId=41
2023-05-12 15:47:05,001 ERROR [capa] [CapaSchedulerWorker.py:38] - TrainValidDataResDto.__init__() got an unexpected keyword argument 'detail'
2023-05-12 15:47:05,007 ERROR [capa] [CapaSchedulerWorker.py:39] - ['  File "<string>", line 1, in <module>\n', '  File "C:\\Users\\wisol\\AppData\\Local\\Programs\\Python\\Python310\\lib\\multiprocessing\\spawn.py", line 116, in spawn_main\n    exitcode = _main(fd, parent_sentinel)\n', '  File "C:\\Users\\wisol\\AppData\\Local\\Programs\\Python\\Python310\\lib\\multiprocessing\\spawn.py", line 129, in _main\n    return self._bootstrap(parent_sentinel)\n', '  File "C:\\Users\\wisol\\AppData\\Local\\Programs\\Python\\Python310\\lib\\multiprocessing\\process.py", line 314, in _bootstrap\n    self.run()\n', '  File "C:\\Users\\wisol\\AppData\\Local\\Programs\\Python\\Python310\\lib\\multiprocessing\\process.py", line 108, in run\n    self._target(*self._args, **self._kwargs)\n', '  File "C:\\webpro\\pythonProject\\fdcmp\\capa\\Process\\CapaProcessWorker.py", line 34, in capaPWorker\n    capaSchedulerWorker.start()\n', '  File "C:\\webpro\\pythonProject\\fdcmp\\capa\\Process\\CapaSchedulerWorker.py", line 39, in start\n    logging.getLogger("capa").error(traceback.format_stack())\n']
2023-05-12 15:47:20,949 INFO [capa] [CapaProcessWorker.py:30] - start process moduleId=41
2023-05-12 15:50:42,646 INFO [capa] [CapaProcessWorker.py:30] - start process moduleId=41
2023-05-12 15:55:01,789 INFO [capa] [CapaProcessWorker.py:30] - start process moduleId=41
2023-05-12 15:55:04,794 ERROR [capa] [CapaProcessWorker.py:37] - type object 'KeyboardInterrupt' has no attribute 'updateTrainValidData'
2023-05-12 15:55:20,897 INFO [capa] [CapaProcessWorker.py:30] - start process moduleId=41
2023-05-12 15:59:07,779 INFO [capa] [CapaProcessWorker.py:30] - start process moduleId=41
2023-05-12 15:59:58,927 ERROR [capa] [CapaSchedulerWorker.py:62] - TrainLogicUpdateReqDto.__init__() missing 1 required positional argument: 'modelType'
2023-05-12 15:59:58,936 ERROR [capa] [CapaSchedulerWorker.py:63] - ['  File "<string>", line 1, in <module>\n', '  File "C:\\Users\\wisol\\AppData\\Local\\Programs\\Python\\Python310\\lib\\multiprocessing\\spawn.py", line 116, in spawn_main\n    exitcode = _main(fd, parent_sentinel)\n', '  File "C:\\Users\\wisol\\AppData\\Local\\Programs\\Python\\Python310\\lib\\multiprocessing\\spawn.py", line 129, in _main\n    return self._bootstrap(parent_sentinel)\n', '  File "C:\\Users\\wisol\\AppData\\Local\\Programs\\Python\\Python310\\lib\\multiprocessing\\process.py", line 314, in _bootstrap\n    self.run()\n', '  File "C:\\Users\\wisol\\AppData\\Local\\Programs\\Python\\Python310\\lib\\multiprocessing\\process.py", line 108, in run\n    self._target(*self._args, **self._kwargs)\n', '  File "C:\\webpro\\pythonProject\\fdcmp\\capa\\Process\\CapaProcessWorker.py", line 34, in capaPWorker\n    capaSchedulerWorker.start()\n', '  File "C:\\webpro\\pythonProject\\fdcmp\\capa\\Process\\CapaSchedulerWorker.py", line 63, in start\n    logging.getLogger("capa").error(traceback.format_stack())\n']
2023-05-12 15:59:59,233 ERROR [capa] [CapaSchedulerWorker.py:78] - PredictParamInfoResDto.__init__() got an unexpected keyword argument 'detail'
2023-05-12 15:59:59,234 ERROR [capa] [CapaSchedulerWorker.py:79] - ['  File "<string>", line 1, in <module>\n', '  File "C:\\Users\\wisol\\AppData\\Local\\Programs\\Python\\Python310\\lib\\multiprocessing\\spawn.py", line 116, in spawn_main\n    exitcode = _main(fd, parent_sentinel)\n', '  File "C:\\Users\\wisol\\AppData\\Local\\Programs\\Python\\Python310\\lib\\multiprocessing\\spawn.py", line 129, in _main\n    return self._bootstrap(parent_sentinel)\n', '  File "C:\\Users\\wisol\\AppData\\Local\\Programs\\Python\\Python310\\lib\\multiprocessing\\process.py", line 314, in _bootstrap\n    self.run()\n', '  File "C:\\Users\\wisol\\AppData\\Local\\Programs\\Python\\Python310\\lib\\multiprocessing\\process.py", line 108, in run\n    self._target(*self._args, **self._kwargs)\n', '  File "C:\\webpro\\pythonProject\\fdcmp\\capa\\Process\\CapaProcessWorker.py", line 34, in capaPWorker\n    capaSchedulerWorker.start()\n', '  File "C:\\webpro\\pythonProject\\fdcmp\\capa\\Process\\CapaSchedulerWorker.py", line 79, in start\n    logging.getLogger("capa").error(traceback.format_stack())\n']
2023-05-12 16:05:46,451 ERROR [capa] [CapaSchedulerWorker.py:62] - TrainLogicUpdateReqDto.__init__() missing 1 required positional argument: 'modelType'
2023-05-12 17:16:00,592 INFO [capa] [CapaProcessWorker.py:30] - start process moduleId=41
2023-05-12 17:17:48,573 INFO [capa] [CapaProcessWorker.py:30] - start process moduleId=41
2023-05-12 17:18:38,960 ERROR [capa] [CapaSchedulerWorker.py:62] - TrainLogicResDto.__init__() got an unexpected keyword argument 'detail'
2023-05-12 17:18:38,966 ERROR [capa] [CapaSchedulerWorker.py:63] - ['  File "<string>", line 1, in <module>\n', '  File "C:\\Users\\wisol\\AppData\\Local\\Programs\\Python\\Python310\\lib\\multiprocessing\\spawn.py", line 116, in spawn_main\n    exitcode = _main(fd, parent_sentinel)\n', '  File "C:\\Users\\wisol\\AppData\\Local\\Programs\\Python\\Python310\\lib\\multiprocessing\\spawn.py", line 129, in _main\n    return self._bootstrap(parent_sentinel)\n', '  File "C:\\Users\\wisol\\AppData\\Local\\Programs\\Python\\Python310\\lib\\multiprocessing\\process.py", line 314, in _bootstrap\n    self.run()\n', '  File "C:\\Users\\wisol\\AppData\\Local\\Programs\\Python\\Python310\\lib\\multiprocessing\\process.py", line 108, in run\n    self._target(*self._args, **self._kwargs)\n', '  File "C:\\webpro\\pythonProject\\fdcmp\\capa\\Process\\CapaProcessWorker.py", line 34, in capaPWorker\n    capaSchedulerWorker.start()\n', '  File "C:\\webpro\\pythonProject\\fdcmp\\capa\\Process\\CapaSchedulerWorker.py", line 63, in start\n    logging.getLogger("capa").error(traceback.format_stack())\n']
2023-05-12 17:18:39,222 ERROR [capa] [CapaSchedulerWorker.py:78] - PredictParamInfoResDto.__init__() got an unexpected keyword argument 'detail'
2023-05-12 17:18:39,223 ERROR [capa] [CapaSchedulerWorker.py:79] - ['  File "<string>", line 1, in <module>\n', '  File "C:\\Users\\wisol\\AppData\\Local\\Programs\\Python\\Python310\\lib\\multiprocessing\\spawn.py", line 116, in spawn_main\n    exitcode = _main(fd, parent_sentinel)\n', '  File "C:\\Users\\wisol\\AppData\\Local\\Programs\\Python\\Python310\\lib\\multiprocessing\\spawn.py", line 129, in _main\n    return self._bootstrap(parent_sentinel)\n', '  File "C:\\Users\\wisol\\AppData\\Local\\Programs\\Python\\Python310\\lib\\multiprocessing\\process.py", line 314, in _bootstrap\n    self.run()\n', '  File "C:\\Users\\wisol\\AppData\\Local\\Programs\\Python\\Python310\\lib\\multiprocessing\\process.py", line 108, in run\n    self._target(*self._args, **self._kwargs)\n', '  File "C:\\webpro\\pythonProject\\fdcmp\\capa\\Process\\CapaProcessWorker.py", line 34, in capaPWorker\n    capaSchedulerWorker.start()\n', '  File "C:\\webpro\\pythonProject\\fdcmp\\capa\\Process\\CapaSchedulerWorker.py", line 79, in start\n    logging.getLogger("capa").error(traceback.format_stack())\n']
2023-05-12 17:22:30,955 INFO [capa] [CapaProcessWorker.py:30] - start process moduleId=41
2023-05-12 17:22:50,230 ERROR [capa] [CapaSchedulerWorker.py:78] - PredictParamInfoResDto.__init__() got an unexpected keyword argument 'detail'
2023-05-12 17:22:50,231 ERROR [capa] [CapaSchedulerWorker.py:79] - ['  File "<string>", line 1, in <module>\n', '  File "C:\\Users\\wisol\\AppData\\Local\\Programs\\Python\\Python310\\lib\\multiprocessing\\spawn.py", line 116, in spawn_main\n    exitcode = _main(fd, parent_sentinel)\n', '  File "C:\\Users\\wisol\\AppData\\Local\\Programs\\Python\\Python310\\lib\\multiprocessing\\spawn.py", line 129, in _main\n    return self._bootstrap(parent_sentinel)\n', '  File "C:\\Users\\wisol\\AppData\\Local\\Programs\\Python\\Python310\\lib\\multiprocessing\\process.py", line 314, in _bootstrap\n    self.run()\n', '  File "C:\\Users\\wisol\\AppData\\Local\\Programs\\Python\\Python310\\lib\\multiprocessing\\process.py", line 108, in run\n    self._target(*self._args, **self._kwargs)\n', '  File "C:\\webpro\\pythonProject\\fdcmp\\capa\\Process\\CapaProcessWorker.py", line 34, in capaPWorker\n    capaSchedulerWorker.start()\n', '  File "C:\\webpro\\pythonProject\\fdcmp\\capa\\Process\\CapaSchedulerWorker.py", line 79, in start\n    logging.getLogger("capa").error(traceback.format_stack())\n']
2023-05-12 17:23:57,236 INFO [capa] [CapaProcessWorker.py:30] - start process moduleId=41
2023-05-15 10:02:30,747 INFO [capa] [CapaProcessWorker.py:30] - start process moduleId=41
2023-05-15 10:05:06,502 INFO [capa] [CapaProcessWorker.py:30] - start process moduleId=41
2023-05-15 10:07:15,574 ERROR [capa] [CapaProcessWorker.py:37] - TrainSchedulerHistoryResDto.__init__() got an unexpected keyword argument 'detail'
2023-05-15 10:07:16,118 ERROR [capa] [CapaProcessWorker.py:38] - ['  File "<string>", line 1, in <module>\n', '  File "C:\\Users\\wisol\\AppData\\Local\\Programs\\Python\\Python310\\lib\\multiprocessing\\spawn.py", line 116, in spawn_main\n    exitcode = _main(fd, parent_sentinel)\n', '  File "C:\\Users\\wisol\\AppData\\Local\\Programs\\Python\\Python310\\lib\\multiprocessing\\spawn.py", line 129, in _main\n    return self._bootstrap(parent_sentinel)\n', '  File "C:\\Users\\wisol\\AppData\\Local\\Programs\\Python\\Python310\\lib\\multiprocessing\\process.py", line 314, in _bootstrap\n    self.run()\n', '  File "C:\\Users\\wisol\\AppData\\Local\\Programs\\Python\\Python310\\lib\\multiprocessing\\process.py", line 108, in run\n    self._target(*self._args, **self._kwargs)\n', '  File "C:\\webpro\\pythonProject\\fdcmp\\capa\\Process\\CapaProcessWorker.py", line 38, in capaPWorker\n    logger.error(traceback.format_stack())\n']
2023-05-15 10:16:04,418 INFO [capa] [CapaProcessWorker.py:30] - start process moduleId=41
2023-05-15 14:51:26,954 INFO [capa] [CapaProcessWorker.py:30] - start process moduleId=41
2023-05-15 14:51:39,785 ERROR [capa] [CapaProcessWorker.py:37] - PredictLogicResDto.__init__() got an unexpected keyword argument 'updateDate'
2023-05-15 14:51:39,787 ERROR [capa] [CapaProcessWorker.py:38] - ['  File "<string>", line 1, in <module>\n', '  File "C:\\Users\\wisol\\AppData\\Local\\Programs\\Python\\Python310\\lib\\multiprocessing\\spawn.py", line 116, in spawn_main\n    exitcode = _main(fd, parent_sentinel)\n', '  File "C:\\Users\\wisol\\AppData\\Local\\Programs\\Python\\Python310\\lib\\multiprocessing\\spawn.py", line 129, in _main\n    return self._bootstrap(parent_sentinel)\n', '  File "C:\\Users\\wisol\\AppData\\Local\\Programs\\Python\\Python310\\lib\\multiprocessing\\process.py", line 314, in _bootstrap\n    self.run()\n', '  File "C:\\Users\\wisol\\AppData\\Local\\Programs\\Python\\Python310\\lib\\multiprocessing\\process.py", line 108, in run\n    self._target(*self._args, **self._kwargs)\n', '  File "C:\\webpro\\pythonProject\\fdcmp\\capa\\Process\\CapaProcessWorker.py", line 38, in capaPWorker\n    logger.error(traceback.format_stack())\n']
2023-05-15 14:52:06,419 INFO [capa] [CapaProcessWorker.py:30] - start process moduleId=41
2023-05-15 14:52:40,059 ERROR [capa] [CapaProcessWorker.py:37] - PredictLogicResDto.__init__() got an unexpected keyword argument 'updateDate'
2023-05-15 14:52:40,061 ERROR [capa] [CapaProcessWorker.py:38] - ['  File "<string>", line 1, in <module>\n', '  File "C:\\Users\\wisol\\AppData\\Local\\Programs\\Python\\Python310\\lib\\multiprocessing\\spawn.py", line 116, in spawn_main\n    exitcode = _main(fd, parent_sentinel)\n', '  File "C:\\Users\\wisol\\AppData\\Local\\Programs\\Python\\Python310\\lib\\multiprocessing\\spawn.py", line 129, in _main\n    return self._bootstrap(parent_sentinel)\n', '  File "C:\\Users\\wisol\\AppData\\Local\\Programs\\Python\\Python310\\lib\\multiprocessing\\process.py", line 314, in _bootstrap\n    self.run()\n', '  File "C:\\Users\\wisol\\AppData\\Local\\Programs\\Python\\Python310\\lib\\multiprocessing\\process.py", line 108, in run\n    self._target(*self._args, **self._kwargs)\n', '  File "C:\\webpro\\pythonProject\\fdcmp\\capa\\Process\\CapaProcessWorker.py", line 38, in capaPWorker\n    logger.error(traceback.format_stack())\n']
2023-05-15 14:53:10,510 INFO [capa] [CapaProcessWorker.py:30] - start process moduleId=41
2023-05-15 14:53:24,508 ERROR [capa] [CapaProcessWorker.py:37] - PredictLogicResDto.__init__() got an unexpected keyword argument 'trainLogic'
2023-05-15 14:53:24,510 ERROR [capa] [CapaProcessWorker.py:38] - ['  File "<string>", line 1, in <module>\n', '  File "C:\\Users\\wisol\\AppData\\Local\\Programs\\Python\\Python310\\lib\\multiprocessing\\spawn.py", line 116, in spawn_main\n    exitcode = _main(fd, parent_sentinel)\n', '  File "C:\\Users\\wisol\\AppData\\Local\\Programs\\Python\\Python310\\lib\\multiprocessing\\spawn.py", line 129, in _main\n    return self._bootstrap(parent_sentinel)\n', '  File "C:\\Users\\wisol\\AppData\\Local\\Programs\\Python\\Python310\\lib\\multiprocessing\\process.py", line 314, in _bootstrap\n    self.run()\n', '  File "C:\\Users\\wisol\\AppData\\Local\\Programs\\Python\\Python310\\lib\\multiprocessing\\process.py", line 108, in run\n    self._target(*self._args, **self._kwargs)\n', '  File "C:\\webpro\\pythonProject\\fdcmp\\capa\\Process\\CapaProcessWorker.py", line 38, in capaPWorker\n    logger.error(traceback.format_stack())\n']
2023-05-15 14:54:26,862 INFO [capa] [CapaProcessWorker.py:30] - start process moduleId=41
2023-05-15 14:55:08,883 ERROR [capa] [CapaSchedulerWorker.py:97] - 'portShare'
2023-05-15 14:55:08,889 ERROR [capa] [CapaSchedulerWorker.py:98] - ['  File "<string>", line 1, in <module>\n', '  File "C:\\Users\\wisol\\AppData\\Local\\Programs\\Python\\Python310\\lib\\multiprocessing\\spawn.py", line 116, in spawn_main\n    exitcode = _main(fd, parent_sentinel)\n', '  File "C:\\Users\\wisol\\AppData\\Local\\Programs\\Python\\Python310\\lib\\multiprocessing\\spawn.py", line 129, in _main\n    return self._bootstrap(parent_sentinel)\n', '  File "C:\\Users\\wisol\\AppData\\Local\\Programs\\Python\\Python310\\lib\\multiprocessing\\process.py", line 314, in _bootstrap\n    self.run()\n', '  File "C:\\Users\\wisol\\AppData\\Local\\Programs\\Python\\Python310\\lib\\multiprocessing\\process.py", line 108, in run\n    self._target(*self._args, **self._kwargs)\n', '  File "C:\\webpro\\pythonProject\\fdcmp\\capa\\Process\\CapaProcessWorker.py", line 34, in capaPWorker\n    capaSchedulerWorker.start()\n', '  File "C:\\webpro\\pythonProject\\fdcmp\\capa\\Process\\CapaSchedulerWorker.py", line 98, in start\n    logging.getLogger("capa").error(traceback.format_stack())\n']
2023-05-15 14:58:22,970 INFO [capa] [CapaProcessWorker.py:30] - start process moduleId=41
2023-05-15 15:00:18,657 INFO [capa] [CapaProcessWorker.py:30] - start process moduleId=41
2023-05-15 15:08:28,294 INFO [capa] [CapaProcessWorker.py:30] - start process moduleId=41
2023-05-15 15:08:28,394 ERROR [capa] [CapaProcessWorker.py:37] - TrainSchedulerHistoryResDto.__init__() got an unexpected keyword argument 'predictResult'
2023-05-15 15:08:28,398 ERROR [capa] [CapaProcessWorker.py:38] - ['  File "<string>", line 1, in <module>\n', '  File "C:\\Users\\wisol\\AppData\\Local\\Programs\\Python\\Python310\\lib\\multiprocessing\\spawn.py", line 116, in spawn_main\n    exitcode = _main(fd, parent_sentinel)\n', '  File "C:\\Users\\wisol\\AppData\\Local\\Programs\\Python\\Python310\\lib\\multiprocessing\\spawn.py", line 129, in _main\n    return self._bootstrap(parent_sentinel)\n', '  File "C:\\Users\\wisol\\AppData\\Local\\Programs\\Python\\Python310\\lib\\multiprocessing\\process.py", line 314, in _bootstrap\n    self.run()\n', '  File "C:\\Users\\wisol\\AppData\\Local\\Programs\\Python\\Python310\\lib\\multiprocessing\\process.py", line 108, in run\n    self._target(*self._args, **self._kwargs)\n', '  File "C:\\webpro\\pythonProject\\fdcmp\\capa\\Process\\CapaProcessWorker.py", line 38, in capaPWorker\n    logger.error(traceback.format_stack())\n']
2023-05-15 15:09:35,626 INFO [capa] [CapaProcessWorker.py:30] - start process moduleId=41
2023-05-15 15:09:35,715 ERROR [capa] [CapaProcessWorker.py:37] - TrainSchedulerHistoryResDto.__init__() got an unexpected keyword argument 'predictResult'
2023-05-15 15:09:35,749 ERROR [capa] [CapaProcessWorker.py:38] - ['  File "<string>", line 1, in <module>\n', '  File "C:\\Users\\wisol\\AppData\\Local\\Programs\\Python\\Python310\\lib\\multiprocessing\\spawn.py", line 116, in spawn_main\n    exitcode = _main(fd, parent_sentinel)\n', '  File "C:\\Users\\wisol\\AppData\\Local\\Programs\\Python\\Python310\\lib\\multiprocessing\\spawn.py", line 129, in _main\n    return self._bootstrap(parent_sentinel)\n', '  File "C:\\Users\\wisol\\AppData\\Local\\Programs\\Python\\Python310\\lib\\multiprocessing\\process.py", line 314, in _bootstrap\n    self.run()\n', '  File "C:\\Users\\wisol\\AppData\\Local\\Programs\\Python\\Python310\\lib\\multiprocessing\\process.py", line 108, in run\n    self._target(*self._args, **self._kwargs)\n', '  File "C:\\webpro\\pythonProject\\fdcmp\\capa\\Process\\CapaProcessWorker.py", line 38, in capaPWorker\n    logger.error(traceback.format_stack())\n']
2023-05-15 15:10:35,834 ERROR [capa] [CapaProcessWorker.py:37] - TrainSchedulerHistoryResDto.__init__() got an unexpected keyword argument 'predictResult'
2023-05-15 15:10:35,839 ERROR [capa] [CapaProcessWorker.py:38] - ['  File "<string>", line 1, in <module>\n', '  File "C:\\Users\\wisol\\AppData\\Local\\Programs\\Python\\Python310\\lib\\multiprocessing\\spawn.py", line 116, in spawn_main\n    exitcode = _main(fd, parent_sentinel)\n', '  File "C:\\Users\\wisol\\AppData\\Local\\Programs\\Python\\Python310\\lib\\multiprocessing\\spawn.py", line 129, in _main\n    return self._bootstrap(parent_sentinel)\n', '  File "C:\\Users\\wisol\\AppData\\Local\\Programs\\Python\\Python310\\lib\\multiprocessing\\process.py", line 314, in _bootstrap\n    self.run()\n', '  File "C:\\Users\\wisol\\AppData\\Local\\Programs\\Python\\Python310\\lib\\multiprocessing\\process.py", line 108, in run\n    self._target(*self._args, **self._kwargs)\n', '  File "C:\\webpro\\pythonProject\\fdcmp\\capa\\Process\\CapaProcessWorker.py", line 38, in capaPWorker\n    logger.error(traceback.format_stack())\n']
2023-05-15 15:10:54,838 INFO [capa] [CapaProcessWorker.py:30] - start process moduleId=41
2023-05-15 15:11:11,014 ERROR [capa] [CapaProcessWorker.py:37] - Object of type ndarray is not JSON serializable
2023-05-15 15:11:11,016 ERROR [capa] [CapaProcessWorker.py:38] - ['  File "<string>", line 1, in <module>\n', '  File "C:\\Users\\wisol\\AppData\\Local\\Programs\\Python\\Python310\\lib\\multiprocessing\\spawn.py", line 116, in spawn_main\n    exitcode = _main(fd, parent_sentinel)\n', '  File "C:\\Users\\wisol\\AppData\\Local\\Programs\\Python\\Python310\\lib\\multiprocessing\\spawn.py", line 129, in _main\n    return self._bootstrap(parent_sentinel)\n', '  File "C:\\Users\\wisol\\AppData\\Local\\Programs\\Python\\Python310\\lib\\multiprocessing\\process.py", line 314, in _bootstrap\n    self.run()\n', '  File "C:\\Users\\wisol\\AppData\\Local\\Programs\\Python\\Python310\\lib\\multiprocessing\\process.py", line 108, in run\n    self._target(*self._args, **self._kwargs)\n', '  File "C:\\webpro\\pythonProject\\fdcmp\\capa\\Process\\CapaProcessWorker.py", line 38, in capaPWorker\n    logger.error(traceback.format_stack())\n']
2023-05-15 15:12:11,201 INFO [capa] [CapaProcessWorker.py:30] - start process moduleId=41
2023-05-15 15:15:27,261 INFO [capa] [CapaProcessWorker.py:30] - start process moduleId=41
2023-05-16 09:19:35,065 INFO [capa] [CapaProcessWorker.py:30] - start process moduleId=41
2023-05-16 09:19:55,943 ERROR [capa] [CapaSchedulerWorker.py:101] - 'TrainValidDataContext' object has no attribute 'getModel'
2023-05-16 09:19:55,945 ERROR [capa] [CapaSchedulerWorker.py:102] - ['  File "<string>", line 1, in <module>\n', '  File "C:\\Users\\wisol\\AppData\\Local\\Programs\\Python\\Python310\\lib\\multiprocessing\\spawn.py", line 116, in spawn_main\n    exitcode = _main(fd, parent_sentinel)\n', '  File "C:\\Users\\wisol\\AppData\\Local\\Programs\\Python\\Python310\\lib\\multiprocessing\\spawn.py", line 129, in _main\n    return self._bootstrap(parent_sentinel)\n', '  File "C:\\Users\\wisol\\AppData\\Local\\Programs\\Python\\Python310\\lib\\multiprocessing\\process.py", line 314, in _bootstrap\n    self.run()\n', '  File "C:\\Users\\wisol\\AppData\\Local\\Programs\\Python\\Python310\\lib\\multiprocessing\\process.py", line 108, in run\n    self._target(*self._args, **self._kwargs)\n', '  File "C:\\webpro\\pythonProject\\fdcmp\\capa\\Process\\CapaProcessWorker.py", line 34, in capaPWorker\n    capaSchedulerWorker.start()\n', '  File "C:\\webpro\\pythonProject\\fdcmp\\capa\\Process\\CapaSchedulerWorker.py", line 102, in start\n    logging.getLogger("capa").error(traceback.format_stack())\n']
2023-05-16 09:22:14,757 INFO [capa] [CapaProcessWorker.py:30] - start process moduleId=41
2023-05-16 09:23:26,005 INFO [capa] [CapaProcessWorker.py:30] - start process moduleId=41
2023-05-18 09:29:34,010 INFO [capa] [CapaProcessWorker.py:30] - start process moduleId=41
