2023-05-04 14:46:46,162 ERROR [capa] [CapaProcessWorker.py:59] - 'MPEqpModule' object has no attribute 'moduleType'
2023-05-04 14:46:46,186 ERROR [capa] [CapaProcessWorker.py:60] - ['  File "C:\\Users\\wisol\\AppData\\Local\\JetBrains\\Toolbox\\apps\\PyCharm-P\\ch-0\\231.8109.197\\plugins\\python\\helpers\\pydev\\pydevd.py", line 2195, in <module>\n    main()\n', '  File "C:\\Users\\wisol\\AppData\\Local\\JetBrains\\Toolbox\\apps\\PyCharm-P\\ch-0\\231.8109.197\\plugins\\python\\helpers\\pydev\\pydevd.py", line 2177, in main\n    globals = debugger.run(setup[\'file\'], None, None, is_module)\n', '  File "C:\\Users\\wisol\\AppData\\Local\\JetBrains\\Toolbox\\apps\\PyCharm-P\\ch-0\\231.8109.197\\plugins\\python\\helpers\\pydev\\pydevd.py", line 1489, in run\n    return self._exec(is_module, entry_point_fn, module_name, file, globals, locals)\n', '  File "C:\\Users\\wisol\\AppData\\Local\\JetBrains\\Toolbox\\apps\\PyCharm-P\\ch-0\\231.8109.197\\plugins\\python\\helpers\\pydev\\pydevd.py", line 1496, in _exec\n    pydev_imports.execfile(file, globals, locals)  # execute the script\n', '  File "C:\\Users\\wisol\\AppData\\Local\\JetBrains\\Toolbox\\apps\\PyCharm-P\\ch-0\\231.8109.197\\plugins\\python\\helpers\\pydev\\_pydev_imps\\_pydev_execfile.py", line 18, in execfile\n    exec(compile(contents+"\\n", file, \'exec\'), glob, loc)\n', '  File "C:\\webpro\\pythonProject\\fdcmp\\manage.py", line 22, in <module>\n    main()\n', '  File "C:\\webpro\\pythonProject\\fdcmp\\manage.py", line 18, in main\n    execute_from_command_line(sys.argv)\n', '  File "C:\\webpro\\pythonProject\\fdcmp\\venv\\lib\\site-packages\\django\\core\\management\\__init__.py", line 446, in execute_from_command_line\n    utility.execute()\n', '  File "C:\\webpro\\pythonProject\\fdcmp\\venv\\lib\\site-packages\\django\\core\\management\\__init__.py", line 398, in execute\n    autoreload.check_errors(django.setup)()\n', '  File "C:\\webpro\\pythonProject\\fdcmp\\venv\\lib\\site-packages\\django\\utils\\autoreload.py", line 64, in wrapper\n    fn(*args, **kwargs)\n', '  File "C:\\webpro\\pythonProject\\fdcmp\\venv\\lib\\site-packages\\django\\__init__.py", line 24, in setup\n    apps.populate(settings.INSTALLED_APPS)\n', '  File "C:\\webpro\\pythonProject\\fdcmp\\venv\\lib\\site-packages\\django\\apps\\registry.py", line 124, in populate\n    app_config.ready()\n', '  File "C:\\webpro\\pythonProject\\fdcmp\\capa\\apps.py", line 14, in ready\n    capaProcessWorker()\n', '  File "C:\\webpro\\pythonProject\\fdcmp\\capa\\Process\\CapaProcessWorker.py", line 60, in capaProcessWorker\n    logger.error(traceback.format_stack())\n']
2023-05-04 14:46:56,436 ERROR [capa] [CapaProcessWorker.py:59] - 'MPEqpModule' object has no attribute 'moduleType'
2023-05-04 14:46:56,439 ERROR [capa] [CapaProcessWorker.py:60] - ['  File "C:\\Users\\wisol\\AppData\\Local\\JetBrains\\Toolbox\\apps\\PyCharm-P\\ch-0\\231.8109.197\\plugins\\python\\helpers\\pydev\\pydevd.py", line 2195, in <module>\n    main()\n', '  File "C:\\Users\\wisol\\AppData\\Local\\JetBrains\\Toolbox\\apps\\PyCharm-P\\ch-0\\231.8109.197\\plugins\\python\\helpers\\pydev\\pydevd.py", line 2177, in main\n    globals = debugger.run(setup[\'file\'], None, None, is_module)\n', '  File "C:\\Users\\wisol\\AppData\\Local\\JetBrains\\Toolbox\\apps\\PyCharm-P\\ch-0\\231.8109.197\\plugins\\python\\helpers\\pydev\\pydevd.py", line 1489, in run\n    return self._exec(is_module, entry_point_fn, module_name, file, globals, locals)\n', '  File "C:\\Users\\wisol\\AppData\\Local\\JetBrains\\Toolbox\\apps\\PyCharm-P\\ch-0\\231.8109.197\\plugins\\python\\helpers\\pydev\\pydevd.py", line 1496, in _exec\n    pydev_imports.execfile(file, globals, locals)  # execute the script\n', '  File "C:\\Users\\wisol\\AppData\\Local\\JetBrains\\Toolbox\\apps\\PyCharm-P\\ch-0\\231.8109.197\\plugins\\python\\helpers\\pydev\\_pydev_imps\\_pydev_execfile.py", line 18, in execfile\n    exec(compile(contents+"\\n", file, \'exec\'), glob, loc)\n', '  File "C:\\webpro\\pythonProject\\fdcmp\\manage.py", line 22, in <module>\n    main()\n', '  File "C:\\webpro\\pythonProject\\fdcmp\\manage.py", line 18, in main\n    execute_from_command_line(sys.argv)\n', '  File "C:\\webpro\\pythonProject\\fdcmp\\venv\\lib\\site-packages\\django\\core\\management\\__init__.py", line 446, in execute_from_command_line\n    utility.execute()\n', '  File "C:\\webpro\\pythonProject\\fdcmp\\venv\\lib\\site-packages\\django\\core\\management\\__init__.py", line 398, in execute\n    autoreload.check_errors(django.setup)()\n', '  File "C:\\webpro\\pythonProject\\fdcmp\\venv\\lib\\site-packages\\django\\utils\\autoreload.py", line 64, in wrapper\n    fn(*args, **kwargs)\n', '  File "C:\\webpro\\pythonProject\\fdcmp\\venv\\lib\\site-packages\\django\\__init__.py", line 24, in setup\n    apps.populate(settings.INSTALLED_APPS)\n', '  File "C:\\webpro\\pythonProject\\fdcmp\\venv\\lib\\site-packages\\django\\apps\\registry.py", line 124, in populate\n    app_config.ready()\n', '  File "C:\\webpro\\pythonProject\\fdcmp\\capa\\apps.py", line 14, in ready\n    capaProcessWorker()\n', '  File "C:\\webpro\\pythonProject\\fdcmp\\capa\\Process\\CapaProcessWorker.py", line 60, in capaProcessWorker\n    logger.error(traceback.format_stack())\n']
2023-05-04 14:47:06,720 ERROR [capa] [CapaProcessWorker.py:59] - 'MPEqpModule' object has no attribute 'moduleType'
2023-05-04 14:47:06,723 ERROR [capa] [CapaProcessWorker.py:60] - ['  File "C:\\Users\\wisol\\AppData\\Local\\JetBrains\\Toolbox\\apps\\PyCharm-P\\ch-0\\231.8109.197\\plugins\\python\\helpers\\pydev\\pydevd.py", line 2195, in <module>\n    main()\n', '  File "C:\\Users\\wisol\\AppData\\Local\\JetBrains\\Toolbox\\apps\\PyCharm-P\\ch-0\\231.8109.197\\plugins\\python\\helpers\\pydev\\pydevd.py", line 2177, in main\n    globals = debugger.run(setup[\'file\'], None, None, is_module)\n', '  File "C:\\Users\\wisol\\AppData\\Local\\JetBrains\\Toolbox\\apps\\PyCharm-P\\ch-0\\231.8109.197\\plugins\\python\\helpers\\pydev\\pydevd.py", line 1489, in run\n    return self._exec(is_module, entry_point_fn, module_name, file, globals, locals)\n', '  File "C:\\Users\\wisol\\AppData\\Local\\JetBrains\\Toolbox\\apps\\PyCharm-P\\ch-0\\231.8109.197\\plugins\\python\\helpers\\pydev\\pydevd.py", line 1496, in _exec\n    pydev_imports.execfile(file, globals, locals)  # execute the script\n', '  File "C:\\Users\\wisol\\AppData\\Local\\JetBrains\\Toolbox\\apps\\PyCharm-P\\ch-0\\231.8109.197\\plugins\\python\\helpers\\pydev\\_pydev_imps\\_pydev_execfile.py", line 18, in execfile\n    exec(compile(contents+"\\n", file, \'exec\'), glob, loc)\n', '  File "C:\\webpro\\pythonProject\\fdcmp\\manage.py", line 22, in <module>\n    main()\n', '  File "C:\\webpro\\pythonProject\\fdcmp\\manage.py", line 18, in main\n    execute_from_command_line(sys.argv)\n', '  File "C:\\webpro\\pythonProject\\fdcmp\\venv\\lib\\site-packages\\django\\core\\management\\__init__.py", line 446, in execute_from_command_line\n    utility.execute()\n', '  File "C:\\webpro\\pythonProject\\fdcmp\\venv\\lib\\site-packages\\django\\core\\management\\__init__.py", line 398, in execute\n    autoreload.check_errors(django.setup)()\n', '  File "C:\\webpro\\pythonProject\\fdcmp\\venv\\lib\\site-packages\\django\\utils\\autoreload.py", line 64, in wrapper\n    fn(*args, **kwargs)\n', '  File "C:\\webpro\\pythonProject\\fdcmp\\venv\\lib\\site-packages\\django\\__init__.py", line 24, in setup\n    apps.populate(settings.INSTALLED_APPS)\n', '  File "C:\\webpro\\pythonProject\\fdcmp\\venv\\lib\\site-packages\\django\\apps\\registry.py", line 124, in populate\n    app_config.ready()\n', '  File "C:\\webpro\\pythonProject\\fdcmp\\capa\\apps.py", line 14, in ready\n    capaProcessWorker()\n', '  File "C:\\webpro\\pythonProject\\fdcmp\\capa\\Process\\CapaProcessWorker.py", line 60, in capaProcessWorker\n    logger.error(traceback.format_stack())\n']
2023-05-04 14:47:16,986 ERROR [capa] [CapaProcessWorker.py:59] - 'MPEqpModule' object has no attribute 'moduleType'
2023-05-04 14:47:17,012 ERROR [capa] [CapaProcessWorker.py:60] - ['  File "C:\\Users\\wisol\\AppData\\Local\\JetBrains\\Toolbox\\apps\\PyCharm-P\\ch-0\\231.8109.197\\plugins\\python\\helpers\\pydev\\pydevd.py", line 2195, in <module>\n    main()\n', '  File "C:\\Users\\wisol\\AppData\\Local\\JetBrains\\Toolbox\\apps\\PyCharm-P\\ch-0\\231.8109.197\\plugins\\python\\helpers\\pydev\\pydevd.py", line 2177, in main\n    globals = debugger.run(setup[\'file\'], None, None, is_module)\n', '  File "C:\\Users\\wisol\\AppData\\Local\\JetBrains\\Toolbox\\apps\\PyCharm-P\\ch-0\\231.8109.197\\plugins\\python\\helpers\\pydev\\pydevd.py", line 1489, in run\n    return self._exec(is_module, entry_point_fn, module_name, file, globals, locals)\n', '  File "C:\\Users\\wisol\\AppData\\Local\\JetBrains\\Toolbox\\apps\\PyCharm-P\\ch-0\\231.8109.197\\plugins\\python\\helpers\\pydev\\pydevd.py", line 1496, in _exec\n    pydev_imports.execfile(file, globals, locals)  # execute the script\n', '  File "C:\\Users\\wisol\\AppData\\Local\\JetBrains\\Toolbox\\apps\\PyCharm-P\\ch-0\\231.8109.197\\plugins\\python\\helpers\\pydev\\_pydev_imps\\_pydev_execfile.py", line 18, in execfile\n    exec(compile(contents+"\\n", file, \'exec\'), glob, loc)\n', '  File "C:\\webpro\\pythonProject\\fdcmp\\manage.py", line 22, in <module>\n    main()\n', '  File "C:\\webpro\\pythonProject\\fdcmp\\manage.py", line 18, in main\n    execute_from_command_line(sys.argv)\n', '  File "C:\\webpro\\pythonProject\\fdcmp\\venv\\lib\\site-packages\\django\\core\\management\\__init__.py", line 446, in execute_from_command_line\n    utility.execute()\n', '  File "C:\\webpro\\pythonProject\\fdcmp\\venv\\lib\\site-packages\\django\\core\\management\\__init__.py", line 398, in execute\n    autoreload.check_errors(django.setup)()\n', '  File "C:\\webpro\\pythonProject\\fdcmp\\venv\\lib\\site-packages\\django\\utils\\autoreload.py", line 64, in wrapper\n    fn(*args, **kwargs)\n', '  File "C:\\webpro\\pythonProject\\fdcmp\\venv\\lib\\site-packages\\django\\__init__.py", line 24, in setup\n    apps.populate(settings.INSTALLED_APPS)\n', '  File "C:\\webpro\\pythonProject\\fdcmp\\venv\\lib\\site-packages\\django\\apps\\registry.py", line 124, in populate\n    app_config.ready()\n', '  File "C:\\webpro\\pythonProject\\fdcmp\\capa\\apps.py", line 14, in ready\n    capaProcessWorker()\n', '  File "C:\\webpro\\pythonProject\\fdcmp\\capa\\Process\\CapaProcessWorker.py", line 60, in capaProcessWorker\n    logger.error(traceback.format_stack())\n']
2023-05-04 16:01:15,076 ERROR [capa] [CapaProcessWorker.py:69] - daemonic processes are not allowed to have children
2023-05-04 16:01:15,091 ERROR [capa] [CapaProcessWorker.py:70] - ['  File "<string>", line 1, in <module>\n', '  File "C:\\Users\\wisol\\AppData\\Local\\Programs\\Python\\Python310\\lib\\multiprocessing\\spawn.py", line 116, in spawn_main\n    exitcode = _main(fd, parent_sentinel)\n', '  File "C:\\Users\\wisol\\AppData\\Local\\Programs\\Python\\Python310\\lib\\multiprocessing\\spawn.py", line 129, in _main\n    return self._bootstrap(parent_sentinel)\n', '  File "C:\\Users\\wisol\\AppData\\Local\\Programs\\Python\\Python310\\lib\\multiprocessing\\process.py", line 314, in _bootstrap\n    self.run()\n', '  File "C:\\Users\\wisol\\AppData\\Local\\Programs\\Python\\Python310\\lib\\multiprocessing\\process.py", line 108, in run\n    self._target(*self._args, **self._kwargs)\n', '  File "C:\\webpro\\pythonProject\\fdcmp\\capa\\Process\\CapaProcessWorker.py", line 29, in capaPWorker\n    apps.populate([\'capa\'])\n', '  File "C:\\webpro\\pythonProject\\fdcmp\\venv\\lib\\site-packages\\django\\apps\\registry.py", line 124, in populate\n    app_config.ready()\n', '  File "C:\\webpro\\pythonProject\\fdcmp\\capa\\apps.py", line 14, in ready\n    capaProcessWorker()\n', '  File "C:\\webpro\\pythonProject\\fdcmp\\capa\\Process\\CapaProcessWorker.py", line 70, in capaProcessWorker\n    logger.error(traceback.format_stack())\n']
2023-05-04 16:01:25,337 ERROR [capa] [CapaProcessWorker.py:69] - daemonic processes are not allowed to have children
2023-05-04 16:01:25,339 ERROR [capa] [CapaProcessWorker.py:70] - ['  File "<string>", line 1, in <module>\n', '  File "C:\\Users\\wisol\\AppData\\Local\\Programs\\Python\\Python310\\lib\\multiprocessing\\spawn.py", line 116, in spawn_main\n    exitcode = _main(fd, parent_sentinel)\n', '  File "C:\\Users\\wisol\\AppData\\Local\\Programs\\Python\\Python310\\lib\\multiprocessing\\spawn.py", line 129, in _main\n    return self._bootstrap(parent_sentinel)\n', '  File "C:\\Users\\wisol\\AppData\\Local\\Programs\\Python\\Python310\\lib\\multiprocessing\\process.py", line 314, in _bootstrap\n    self.run()\n', '  File "C:\\Users\\wisol\\AppData\\Local\\Programs\\Python\\Python310\\lib\\multiprocessing\\process.py", line 108, in run\n    self._target(*self._args, **self._kwargs)\n', '  File "C:\\webpro\\pythonProject\\fdcmp\\capa\\Process\\CapaProcessWorker.py", line 29, in capaPWorker\n    apps.populate([\'capa\'])\n', '  File "C:\\webpro\\pythonProject\\fdcmp\\venv\\lib\\site-packages\\django\\apps\\registry.py", line 124, in populate\n    app_config.ready()\n', '  File "C:\\webpro\\pythonProject\\fdcmp\\capa\\apps.py", line 14, in ready\n    capaProcessWorker()\n', '  File "C:\\webpro\\pythonProject\\fdcmp\\capa\\Process\\CapaProcessWorker.py", line 70, in capaProcessWorker\n    logger.error(traceback.format_stack())\n']
2023-05-04 16:13:23,962 INFO [capa] [CapaProcessWorker.py:32] - start process moduleId=41
2023-05-04 16:22:25,395 INFO [capa] [CapaProcessWorker.py:32] - start process moduleId=41
2023-05-04 16:22:46,810 INFO [capa] [CapaProcessWorker.py:32] - start process moduleId=41
2023-05-04 16:23:28,671 INFO [capa] [CapaProcessWorker.py:32] - start process moduleId=41
2023-05-04 16:24:14,998 INFO [capa] [CapaProcessWorker.py:32] - start process moduleId=41
2023-05-04 16:24:42,798 INFO [capa] [CapaProcessWorker.py:32] - start process moduleId=41
2023-05-04 16:25:36,213 INFO [capa] [CapaProcessWorker.py:32] - start process moduleId=41
2023-05-04 16:53:26,319 INFO [capa] [CapaProcessWorker.py:35] - start process moduleId=41
2023-05-04 16:54:37,637 INFO [capa] [CapaProcessWorker.py:35] - start process moduleId=41
2023-05-04 16:55:37,889 INFO [capa] [CapaProcessWorker.py:35] - start process moduleId=41
2023-05-04 16:55:38,001 ERROR [capa] [CapaProcessWorker.py:44] - bFdcAPI.Capa.Dto.TrainSchedulerHistory.TrainSchedulerHistoryResDto() argument after ** must be a mapping, not str
2023-05-04 16:55:38,006 ERROR [capa] [CapaProcessWorker.py:45] - ['  File "<string>", line 1, in <module>\n', '  File "C:\\Users\\wisol\\AppData\\Local\\Programs\\Python\\Python310\\lib\\multiprocessing\\spawn.py", line 116, in spawn_main\n    exitcode = _main(fd, parent_sentinel)\n', '  File "C:\\Users\\wisol\\AppData\\Local\\Programs\\Python\\Python310\\lib\\multiprocessing\\spawn.py", line 129, in _main\n    return self._bootstrap(parent_sentinel)\n', '  File "C:\\Users\\wisol\\AppData\\Local\\Programs\\Python\\Python310\\lib\\multiprocessing\\process.py", line 314, in _bootstrap\n    self.run()\n', '  File "C:\\Users\\wisol\\AppData\\Local\\Programs\\Python\\Python310\\lib\\multiprocessing\\process.py", line 108, in run\n    self._target(*self._args, **self._kwargs)\n', '  File "C:\\webpro\\pythonProject\\fdcmp\\capa\\Process\\CapaProcessWorker.py", line 45, in capaPWorker\n    logger.error(traceback.format_stack())\n']
2023-05-04 16:55:46,990 ERROR [capa] [CapaProcessWorker.py:44] - bFdcAPI.Capa.Dto.TrainSchedulerHistory.TrainSchedulerHistoryResDto() argument after ** must be a mapping, not str
2023-05-04 16:55:46,993 ERROR [capa] [CapaProcessWorker.py:45] - ['  File "<string>", line 1, in <module>\n', '  File "C:\\Users\\wisol\\AppData\\Local\\Programs\\Python\\Python310\\lib\\multiprocessing\\spawn.py", line 116, in spawn_main\n    exitcode = _main(fd, parent_sentinel)\n', '  File "C:\\Users\\wisol\\AppData\\Local\\Programs\\Python\\Python310\\lib\\multiprocessing\\spawn.py", line 129, in _main\n    return self._bootstrap(parent_sentinel)\n', '  File "C:\\Users\\wisol\\AppData\\Local\\Programs\\Python\\Python310\\lib\\multiprocessing\\process.py", line 314, in _bootstrap\n    self.run()\n', '  File "C:\\Users\\wisol\\AppData\\Local\\Programs\\Python\\Python310\\lib\\multiprocessing\\process.py", line 108, in run\n    self._target(*self._args, **self._kwargs)\n', '  File "C:\\webpro\\pythonProject\\fdcmp\\capa\\Process\\CapaProcessWorker.py", line 45, in capaPWorker\n    logger.error(traceback.format_stack())\n']
2023-05-04 16:56:12,598 ERROR [capa] [CapaProcessWorker.py:44] - bFdcAPI.Capa.Dto.TrainSchedulerHistory.TrainSchedulerHistoryResDto() argument after ** must be a mapping, not str
2023-05-04 16:56:12,602 ERROR [capa] [CapaProcessWorker.py:45] - ['  File "<string>", line 1, in <module>\n', '  File "C:\\Users\\wisol\\AppData\\Local\\Programs\\Python\\Python310\\lib\\multiprocessing\\spawn.py", line 116, in spawn_main\n    exitcode = _main(fd, parent_sentinel)\n', '  File "C:\\Users\\wisol\\AppData\\Local\\Programs\\Python\\Python310\\lib\\multiprocessing\\spawn.py", line 129, in _main\n    return self._bootstrap(parent_sentinel)\n', '  File "C:\\Users\\wisol\\AppData\\Local\\Programs\\Python\\Python310\\lib\\multiprocessing\\process.py", line 314, in _bootstrap\n    self.run()\n', '  File "C:\\Users\\wisol\\AppData\\Local\\Programs\\Python\\Python310\\lib\\multiprocessing\\process.py", line 108, in run\n    self._target(*self._args, **self._kwargs)\n', '  File "C:\\webpro\\pythonProject\\fdcmp\\capa\\Process\\CapaProcessWorker.py", line 45, in capaPWorker\n    logger.error(traceback.format_stack())\n']
2023-05-04 16:56:44,746 ERROR [capa] [CapaProcessWorker.py:44] - bFdcAPI.Capa.Dto.TrainSchedulerHistory.TrainSchedulerHistoryResDto() argument after ** must be a mapping, not str
2023-05-04 16:56:44,752 ERROR [capa] [CapaProcessWorker.py:45] - ['  File "<string>", line 1, in <module>\n', '  File "C:\\Users\\wisol\\AppData\\Local\\Programs\\Python\\Python310\\lib\\multiprocessing\\spawn.py", line 116, in spawn_main\n    exitcode = _main(fd, parent_sentinel)\n', '  File "C:\\Users\\wisol\\AppData\\Local\\Programs\\Python\\Python310\\lib\\multiprocessing\\spawn.py", line 129, in _main\n    return self._bootstrap(parent_sentinel)\n', '  File "C:\\Users\\wisol\\AppData\\Local\\Programs\\Python\\Python310\\lib\\multiprocessing\\process.py", line 314, in _bootstrap\n    self.run()\n', '  File "C:\\Users\\wisol\\AppData\\Local\\Programs\\Python\\Python310\\lib\\multiprocessing\\process.py", line 108, in run\n    self._target(*self._args, **self._kwargs)\n', '  File "C:\\webpro\\pythonProject\\fdcmp\\capa\\Process\\CapaProcessWorker.py", line 45, in capaPWorker\n    logger.error(traceback.format_stack())\n']
2023-05-04 16:57:13,306 INFO [capa] [CapaProcessWorker.py:35] - start process moduleId=41
